Workbook

Sheet Question 1
B2: STAGE 1 (Data Cleaning) | E2: We are a part of XYZ Co Pvt Ltd company who is in the business of organizing the sports events at international level. Countries nominate sportsmen from different departments and our team has been given the responsibility to systematize the membership roster and generate different reports as per business requirements.
C5: SHEET | D5: COLUMN | E5: TASK
B6: S No | C6: TASK 1: STANDARDIZING THE DATASET
B7: 1 | C7: SPORTSMEN | D7: Col B | E7: Populate the FULLNAME consisting of the following fields ONLY, in the prescribed format: PREFIX FIRSTNAME LASTNAME. (Note: All UPPERCASE)
B8: 2 | C8: SPORTSMEN | D8: Col K | E8: Get the COUNTRY NAME to which these sportsmen belong to. Make use of LOCATION sheet to get the required data
B9: 3 | C9: SPORTSMEN | D9: Col L | E9: Populate the LANGUAGE spoken by the sportsmen. Make use of LOCATION sheet to get the required data
B10: 4 | C10: SPORTSMEN | D10: Col M | E10: Generate the EMAIL ADDRESS for those members, who speak English, in the prescribed format : lastname.firstname@xyz.org (Note: All lowercase) and for all other members, format should be lastname.firstname@xyz.com (Note: All lowercase)
B11: 5 | C11: SPORTSMEN | D11: Col Q | E11: Populate the SPORT LOCATION of the sport played by each player. Make use of SPORT sheet to get the required data
B13: S No | C13: TASK 2: DATA FORMATTING
B14: 1 | C14: SPORTSMEN | D14: Col A | E14: Display MEMBER ID as always 3 digit number (Note: 001, 002…, 020,… etc)
B15: 2 | C15: SPORTSMEN | D15: Col G | E15: Format the BIRTHDATE as dd mmm' yyyy (Prescribed format example: 09 May' 1986)
B16: 3 | C16: SPORTSMEN | D16: Col N | E16: Display the units for the WEIGHT column (Prescribed format example: 80 kg)
B17: 4 | C17: SPORTSMEN | D17: Col S | E17: Format the SALARY to show the data in thousands. If SALARY is less than 100,000 then display data with 2 decimal places else display data with one decimal place. In both cases units should be thousands (k) e.g. 87670 --> 87.67 k and 123250 --> 123.2 k

Sheet Question 2
B2: STAGE 2 (Data Analysis) | E2: We are a part of XYZ Co Pvt Ltd company who is in the business of organizing the sports events at international level. Countries nominate sportsmen from different departments and our team has been given the responsibility to systematize the membership roster and generate different reports as per business requirements.
B5: Instructions: Make use of data from SPORTSMEN worksheet after attempting Question 1
C6: SHEET | D6: RANGE | E6: TASK
B7: S No | C7: TASK 1: SUMMARIZE DATA - PIVOT TABLE
B8: 1 | C8: ANALYSIS | D8: Range B3 | E8: Create a PIVOT table in the worksheet ANALYSIS, starting at cell B3, with the following details:
B9: 2 | C9: ANALYSIS | E9: In COLUMNS; Group : GENDER.
B10: 3 | C10: ANALYSIS | E10: In ROWS; Group : COUNTRY (Note: use COUNTRY NAMES)
B11: 4 | C11: ANALYSIS | E11: In VALUES; Calculate the count of candidates from each COUNTRY and GENDER type
B12: 5 | C12: ANALYSIS | E12: Remove GRAND TOTALs
B14: S No | C14: TASK 2: SUMMARIZE DATA - EXCEL FUNCTIONS
B15: 1 | C15: ANALYSIS | D15: Range G4 | E15: Create a SUMMARY table in the worksheet ANALYSIS, starting at cell G4, with the following details.
B16: 2 | C16: ANALYSIS | D16: Range H4:I4 | E16: Starting from range RANGE H4; get the distinct GENDER. Use remove duplicates option and transpose the data
B17: 3 | C17: ANALYSIS | D17: Range G5:G16 | E17: Starting from range RANGE G5; get the distinct COUNTRY (Note: use COUNTRY NAMES)
B18: 4 | C18: ANALYSIS | D18: Range H5:I16 | E18: In the cross table, get the count of candidates from each COUNTRY and GENDER type

Sheet Question 3
B2: STAGE 3 (Generate Report) | E2: We are a part of XYZ Co Pvt Ltd company who is in the business of organizing the sports events at international level. Countries nominate sportsmen from different departments and our team has been given the responsibility to systematize the membership roster and generate different reports as per business requirements.
B5: Instructions: Make use of data from SPORTSMEN worksheet after attempting Question 1
C6: SHEET | D6: RANGE | E6: TASK
B7: S No | C7: GENERATE REPORT - PIVOT TABLE
B8: 1 | C8: REPORT | D8: Range A3 | E8: Create a PIVOT table report in the worksheet REPORT, starting at cell A3, with the following information.
B9: 2 | C9: REPORT | E9: Report should contain MEMBER ID, FULL NAME, EMAIL, GENDER, YEAR OF BIRTH (Note: don't display quarters, months and dates), COUNTRY NAME, LANGUAGE and SPORT played by them
B10: 3 | C10: REPORT | E10: Change the report layout to TABULAR form
B11: 4 | C11: REPORT | E11: Remove expand and collapse buttons
B12: 5 | C12: REPORT | E12: Remove GRAND TOTALs
B13: 5 | C13: REPORT | D13: Range A1 | E13: Allow user to filter the data by SPORT LOCATION

Sheet ANALYSIS
B3: Count of MEMBER ID | C3: Column Labels
B4: Row Labels | C4: Female | D4: Male | G4: Gender\ Country | H4: Male | I4: Female
B5: ARGENTINA | C5: 1 | D5: 2 | G5: USA | H5: =COUNTIFS(SPORTSMEN!$K$2:$K$51,ANALYSIS!$G5,SPORTSMEN!$I$2:$I$51,ANALYSIS!H$4) -> 3 | I5: =COUNTIFS(SPORTSMEN!$K$2:$K$51,ANALYSIS!$G5,SPORTSMEN!$I$2:$I$51,ANALYSIS!I$4) -> 4
B6: AUSTRALIA | C6: 6 | D6: 2 | G6: BRAZIL | H6: =COUNTIFS(SPORTSMEN!$K$2:$K$51,ANALYSIS!$G6,SPORTSMEN!$I$2:$I$51,ANALYSIS!H$4) -> 2 | I6: =COUNTIFS(SPORTSMEN!$K$2:$K$51,ANALYSIS!$G6,SPORTSMEN!$I$2:$I$51,ANALYSIS!I$4) -> 0
B7: AUSTRIA | C7: 1 | D7: 2 | G7: UK | H7: =COUNTIFS(SPORTSMEN!$K$2:$K$51,ANALYSIS!$G7,SPORTSMEN!$I$2:$I$51,ANALYSIS!H$4) -> 2 | I7: =COUNTIFS(SPORTSMEN!$K$2:$K$51,ANALYSIS!$G7,SPORTSMEN!$I$2:$I$51,ANALYSIS!I$4) -> 3
B8: BRAZIL | D8: 2 | G8: GERMANY | H8: =COUNTIFS(SPORTSMEN!$K$2:$K$51,ANALYSIS!$G8,SPORTSMEN!$I$2:$I$51,ANALYSIS!H$4) -> 4 | I8: =COUNTIFS(SPORTSMEN!$K$2:$K$51,ANALYSIS!$G8,SPORTSMEN!$I$2:$I$51,ANALYSIS!I$4) -> 1
B9: FRANCE | C9: 3 | D9: 6 | G9: AUSTRALIA | H9: =COUNTIFS(SPORTSMEN!$K$2:$K$51,ANALYSIS!$G9,SPORTSMEN!$I$2:$I$51,ANALYSIS!H$4) -> 2 | I9: =COUNTIFS(SPORTSMEN!$K$2:$K$51,ANALYSIS!$G9,SPORTSMEN!$I$2:$I$51,ANALYSIS!I$4) -> 6
B10: GERMANY | C10: 1 | D10: 4 | G10: AUSTRIA | H10: =COUNTIFS(SPORTSMEN!$K$2:$K$51,ANALYSIS!$G10,SPORTSMEN!$I$2:$I$51,ANALYSIS!H$4) -> 2 | I10: =COUNTIFS(SPORTSMEN!$K$2:$K$51,ANALYSIS!$G10,SPORTSMEN!$I$2:$I$51,ANALYSIS!I$4) -> 1
B11: NETHERLANDS | C11: 2 | D11: 1 | G11: FRANCE | H11: =COUNTIFS(SPORTSMEN!$K$2:$K$51,ANALYSIS!$G11,SPORTSMEN!$I$2:$I$51,ANALYSIS!H$4) -> 6 | I11: =COUNTIFS(SPORTSMEN!$K$2:$K$51,ANALYSIS!$G11,SPORTSMEN!$I$2:$I$51,ANALYSIS!I$4) -> 3
B12: SPAIN | C12: 3 | G12: ARGENTINA | H12: =COUNTIFS(SPORTSMEN!$K$2:$K$51,ANALYSIS!$G12,SPORTSMEN!$I$2:$I$51,ANALYSIS!H$4) -> 2 | I12: =COUNTIFS(SPORTSMEN!$K$2:$K$51,ANALYSIS!$G12,SPORTSMEN!$I$2:$I$51,ANALYSIS!I$4) -> 1
B13: SWEDEN | C13: 1 | D13: 1 | G13: SPAIN | H13: =COUNTIFS(SPORTSMEN!$K$2:$K$51,ANALYSIS!$G13,SPORTSMEN!$I$2:$I$51,ANALYSIS!H$4) -> 0 | I13: =COUNTIFS(SPORTSMEN!$K$2:$K$51,ANALYSIS!$G13,SPORTSMEN!$I$2:$I$51,ANALYSIS!I$4) -> 3
B14: UK | C14: 3 | D14: 2 | G14: NETHERLANDS | H14: =COUNTIFS(SPORTSMEN!$K$2:$K$51,ANALYSIS!$G14,SPORTSMEN!$I$2:$I$51,ANALYSIS!H$4) -> 1 | I14: =COUNTIFS(SPORTSMEN!$K$2:$K$51,ANALYSIS!$G14,SPORTSMEN!$I$2:$I$51,ANALYSIS!I$4) -> 2
B15: USA | C15: 4 | D15: 3 | G15: SWEDEN | H15: =COUNTIFS(SPORTSMEN!$K$2:$K$51,ANALYSIS!$G15,SPORTSMEN!$I$2:$I$51,ANALYSIS!H$4) -> 1 | I15: =COUNTIFS(SPORTSMEN!$K$2:$K$51,ANALYSIS!$G15,SPORTSMEN!$I$2:$I$51,ANALYSIS!I$4) -> 1

Sheet REPORT
A3: MEMBER ID | B3: COUNTRY NAME | C3: FULL NAME | D3: EMAIL | E3: GENDER | F3: Years (BIRTHDATE) | G3: BIRTHDATE | H3: LANGUAGE | I3: SPORTS
A4: 1 | B4: USA | C4: MS. ANNIE ABBOTT | D4: abbott.annie@xyz.org | E4: Female | F4: 1997 | G4: 35699 | H4: English | I4: Cycling Track
A5: 1 | B5: USA | C5: MS. ANNIE ABBOTT | D5: abbott.annie@xyz.org | E5: Female | F5: 1997 | G5: 35699 | H5: English Total
A6: 1 | B6: USA | C6: MS. ANNIE ABBOTT | D6: abbott.annie@xyz.org | E6: Female | F6: 1997 | G6: 26-09-1997 Total
A7: 1 | B7: USA | C7: MS. ANNIE ABBOTT | D7: abbott.annie@xyz.org | E7: Female | F7: 1997 Total
A8: 1 | B8: USA | C8: MS. ANNIE ABBOTT | D8: abbott.annie@xyz.org | E8: Female Total
A9: 1 | B9: USA | C9: MS. ANNIE ABBOTT | D9: abbott.annie@xyz.org Total
A10: 1 | B10: USA | C10: MS. ANNIE ABBOTT Total
A11: 1 | B11: USA Total
A12: 1 Total
A13: 2 | B13: USA | C13: MS. AURELIE LIESUCHKE | D13: liesuchke.aurelie@xyz.org | E13: Female | F13: 1992 | G13: 33641 | H13: English | I13: Boxing
A14: 2 | B14: USA | C14: MS. AURELIE LIESUCHKE | D14: liesuchke.aurelie@xyz.org | E14: Female | F14: 1992 | G14: 33641 | H14: English Total
A15: 2 | B15: USA | C15: MS. AURELIE LIESUCHKE | D15: liesuchke.aurelie@xyz.org | E15: Female | F15: 1992 | G15: 07-02-1992 Total
A16: 2 | B16: USA | C16: MS. AURELIE LIESUCHKE | D16: liesuchke.aurelie@xyz.org | E16: Female | F16: 1992 Total
A17: 2 | B17: USA | C17: MS. AURELIE LIESUCHKE | D17: liesuchke.aurelie@xyz.org | E17: Female Total
A18: 2 | B18: USA | C18: MS. AURELIE LIESUCHKE | D18: liesuchke.aurelie@xyz.org Total
A19: 2 | B19: USA | C19: MS. AURELIE LIESUCHKE Total
A20: 2 | B20: USA Total
A21: 2 Total
A22: 3 | B22: BRAZIL | C22: SR. TOMAS FILHO | D22: filho.tomas@xyz.com | E22: Male | F22: 1969 | G22: 25394 | H22: Portuguese | I22: Football
A23: 3 | B23: BRAZIL | C23: SR. TOMAS FILHO | D23: filho.tomas@xyz.com | E23: Male | F23: 1969 | G23: 25394 | H23: Portuguese Total
A24: 3 | B24: BRAZIL | C24: SR. TOMAS FILHO | D24: filho.tomas@xyz.com | E24: Male | F24: 1969 | G24: 10-07-1969 Total
A25: 3 | B25: BRAZIL | C25: SR. TOMAS FILHO | D25: filho.tomas@xyz.com | E25: Male | F25: 1969 Total
A26: 3 | B26: BRAZIL | C26: SR. TOMAS FILHO | D26: filho.tomas@xyz.com | E26: Male Total
A27: 3 | B27: BRAZIL | C27: SR. TOMAS FILHO | D27: filho.tomas@xyz.com Total
A28: 3 | B28: BRAZIL | C28: SR. TOMAS FILHO Total
A29: 3 | B29: BRAZIL Total
A30: 3 Total
A31: 4 | B31: USA | C31: MS. DARBY CRUICKSHANK | D31: cruickshank.darby@xyz.org | E31: Female | F31: 1975 | G31: 27532 | H31: English | I31: Alpine Skiing
A32: 4 | B32: USA | C32: MS. DARBY CRUICKSHANK | D32: cruickshank.darby@xyz.org | E32: Female | F32: 1975 | G32: 27532 | H32: English Total
A33: 4 | B33: USA | C33: MS. DARBY CRUICKSHANK | D33: cruickshank.darby@xyz.org | E33: Female | F33: 1975 | G33: 18-05-1975 Total
A34: 4 | B34: USA | C34: MS. DARBY CRUICKSHANK | D34: cruickshank.darby@xyz.org | E34: Female | F34: 1975 Total
A35: 4 | B35: USA | C35: MS. DARBY CRUICKSHANK | D35: cruickshank.darby@xyz.org | E35: Female Total
A36: 4 | B36: USA | C36: MS. DARBY CRUICKSHANK | D36: cruickshank.darby@xyz.org Total
A37: 4 | B37: USA | C37: MS. DARBY CRUICKSHANK Total
A38: 4 | B38: USA Total
A39: 4 Total
A40: 5 | B40: USA | C40: DR. JAYDON BORER | D40: borer.jaydon@xyz.org | E40: Male | F40: 1970 | G40: 25706 | H40: English | I40: Water Polo
A41: 5 | B41: USA | C41: DR. JAYDON BORER | D41: borer.jaydon@xyz.org | E41: Male | F41: 1970 | G41: 25706 | H41: English Total
A42: 5 | B42: USA | C42: DR. JAYDON BORER | D42: borer.jaydon@xyz.org | E42: Male | F42: 1970 | G42: 18-05-1970 Total
...

Sheet SPORTSMEN
A1: MEMBER ID | B1: FULL NAME | C1: PREFIX | D1: FIRSTNAME | E1: MIDDLENAME | F1: LASTNAME | G1: BIRTHDATE | H1: ZODIAC | I1: GENDER | J1: COUNTRYCODE | K1: COUNTRY NAME | L1: LANGUAGE | M1: EMAIL | N1: WEIGHT | O1: EYECOLOR | P1: BLOODTYPE | Q1: SPORT LOCATION | R1: SPORTS | S1: SALARY
A2: 1 | B2: =UPPER(_xlfn.CONCAT(C2&" "&D2&" "&F2)) -> MS. ANNIE ABBOTT | C2: Ms. | D2: Annie | F2: Abbott | G2: 35699 | H2: Libra | I2: Female | J2: US | K2: =HLOOKUP($J2,LOCATION!$A$2:$M$3,2,FALSE) -> USA | L2: =_xlfn.XLOOKUP($J2,LOCATION!$A$2:$M$2,LOCATION!$A$1:$M$1) -> English | M2: =LOWER(IF($L2="English",$F2&"."&$D2&"@xyz.org",$F2&"."&$D2&"@xyz.com")) -> abbott.annie@xyz.org | N2: 94 | O2: Green | P2: A− | Q2: =_xlfn.XLOOKUP($R2,SPORT!$B$1:$B$33,SPORT!$A$1:$A$33) -> INDOOR | R2: Cycling Track | S2: 80727
A3: 2 | B3: =UPPER(_xlfn.CONCAT(C3&" "&D3&" "&F3)) -> MS. AURELIE LIESUCHKE | C3: Ms. | D3: Aurelie | F3: Liesuchke | G3: 33641 | H3: Aquarius | I3: Female | J3: US | K3: =HLOOKUP($J3,LOCATION!$A$2:$M$3,2,FALSE) -> USA | L3: =_xlfn.XLOOKUP($J3,LOCATION!$A$2:$M$2,LOCATION!$A$1:$M$1) -> English | M3: =LOWER(IF($L3="English",$F3&"."&$D3&"@xyz.org",$F3&"."&$D3&"@xyz.com")) -> liesuchke.aurelie@xyz.org | N3: 84.2 | O3: Brown | P3: O− | Q3: =_xlfn.XLOOKUP($R3,SPORT!$B$1:$B$33,SPORT!$A$1:$A$33) -> INDOOR | R3: Boxing | S3: 87471
A4: 3 | B4: =UPPER(_xlfn.CONCAT(C4&" "&D4&" "&F4)) -> SR. TOMAS FILHO | C4: Sr. | D4: Tomas | E4: Ferreira | F4: Filho | G4: 25394 | H4: Cancer | I4: Male | J4: BR | K4: =HLOOKUP($J4,LOCATION!$A$2:$M$3,2,FALSE) -> BRAZIL | L4: =_xlfn.XLOOKUP($J4,LOCATION!$A$2:$M$2,LOCATION!$A$1:$M$1) -> Portuguese | M4: =LOWER(IF($L4="English",$F4&"."&$D4&"@xyz.org",$F4&"."&$D4&"@xyz.com")) -> filho.tomas@xyz.com | N4: 52.9 | O4: Amber | P4: A− | Q4: =_xlfn.XLOOKUP($R4,SPORT!$B$1:$B$33,SPORT!$A$1:$A$33) -> OUTDOOR | R4: Football | S4: 64724
A5: 4 | B5: =UPPER(_xlfn.CONCAT(C5&" "&D5&" "&F5)) -> MS. DARBY CRUICKSHANK | C5: Ms. | D5: Darby | F5: Cruickshank | G5: 27532 | H5: Taurus | I5: Female | J5: US | K5: =HLOOKUP($J5,LOCATION!$A$2:$M$3,2,FALSE) -> USA | L5: =_xlfn.XLOOKUP($J5,LOCATION!$A$2:$M$2,LOCATION!$A$1:$M$1) -> English | M5: =LOWER(IF($L5="English",$F5&"."&$D5&"@xyz.org",$F5&"."&$D5&"@xyz.com")) -> cruickshank.darby@xyz.org | N5: 48.9 | O5: Green | P5: O− | Q5: =_xlfn.XLOOKUP($R5,SPORT!$B$1:$B$33,SPORT!$A$1:$A$33) -> OUTDOOR | R5: Alpine Skiing | S5: 110823
A6: 5 | B6: =UPPER(_xlfn.CONCAT(C6&" "&D6&" "&F6)) -> DR. JAYDON BORER | C6: Dr. | D6: Jaydon | F6: Borer | G6: 25706 | H6: Taurus | I6: Male | J6: US | K6: =HLOOKUP($J6,LOCATION!$A$2:$M$3,2,FALSE) -> USA | L6: =_xlfn.XLOOKUP($J6,LOCATION!$A$2:$M$2,LOCATION!$A$1:$M$1) -> English | M6: =LOWER(IF($L6="English",$F6&"."&$D6&"@xyz.org",$F6&"."&$D6&"@xyz.com")) -> borer.jaydon@xyz.org | N6: 84.8 | O6: Blue | P6: B− | Q6: =_xlfn.XLOOKUP($R6,SPORT!$B$1:$B$33,SPORT!$A$1:$A$33) -> INDOOR | R6: Water Polo | S6: 56916
A7: 6 | B7: =UPPER(_xlfn.CONCAT(C7&" "&D7&" "&F7)) -> MR. MORIAH LYNCH | C7: Mr. | D7: Moriah | F7: Lynch | G7: 33944 | H7: Sagittarius | I7: Male | J7: US | K7: =HLOOKUP($J7,LOCATION!$A$2:$M$3,2,FALSE) -> USA | L7: =_xlfn.XLOOKUP($J7,LOCATION!$A$2:$M$2,LOCATION!$A$1:$M$1) -> English | M7: =LOWER(IF($L7="English",$F7&"."&$D7&"@xyz.org",$F7&"."&$D7&"@xyz.com")) -> lynch.moriah @xyz.org | N7: 83.2 | O7: Blue | P7: O− | Q7: =_xlfn.XLOOKUP($R7,SPORT!$B$1:$B$33,SPORT!$A$1:$A$33) -> INDOOR | R7: Fencing | S7: 51133
A8: 7 | B8: =UPPER(_xlfn.CONCAT(C8&" "&D8&" "&F8)) -> MS. AMIYA EICHMANN | C8: Ms. | D8: Amiya | F8: Eichmann | G8: 36370 | H8: Leo | I8: Female | J8: US | K8: =HLOOKUP($J8,LOCATION!$A$2:$M$3,2,FALSE) -> USA | L8: =_xlfn.XLOOKUP($J8,LOCATION!$A$2:$M$2,LOCATION!$A$1:$M$1) -> English | M8: =LOWER(IF($L8="English",$F8&"."&$D8&"@xyz.org",$F8&"."&$D8&"@xyz.com")) -> eichmann.amiya@xyz.org | N8: 61.1 | O8: Blue | P8: B− | Q8: =_xlfn.XLOOKUP($R8,SPORT!$B$1:$B$33,SPORT!$A$1:$A$33) -> OUTDOOR | R8: Cycling Road | S8: 65465
A9: 8 | B9: =UPPER(_xlfn.CONCAT(C9&" "&D9&" "&F9)) -> MR. PIERCE RAU | C9: Mr. | D9: Pierce | F9: Rau | G9: 23141 | H9: Taurus | I9: Male | J9: US | K9: =HLOOKUP($J9,LOCATION!$A$2:$M$3,2,FALSE) -> USA | L9: =_xlfn.XLOOKUP($J9,LOCATION!$A$2:$M$2,LOCATION!$A$1:$M$1) -> English | M9: =LOWER(IF($L9="English",$F9&"."&$D9&"@xyz.org",$F9&"."&$D9&"@xyz.com")) -> rau.pierce@xyz.org | N9: 105.7 | O9: Amber | P9: A+ | Q9: =_xlfn.XLOOKUP($R9,SPORT!$B$1:$B$33,SPORT!$A$1:$A$33) -> INDOOR | R9: Curling | S9: 109885
A10: 9 | B10: =UPPER(_xlfn.CONCAT(C10&" "&D10&" "&F10)) -> MS. AMELIA STEVENS | C10: Ms. | D10: Amelia | F10: Stevens | G10: 25965 | H10: Aquarius | I10: Female | J10: GB | K10: =HLOOKUP($J10,LOCATION!$A$2:$M$3,2,FALSE) -> UK | L10: =_xlfn.XLOOKUP($J10,LOCATION!$A$2:$M$2,LOCATION!$A$1:$M$1) -> English | M10: =LOWER(IF($L10="English",$F10&"."&$D10&"@xyz.org",$F10&"."&$D10&"@xyz.com")) -> stevens.amelia@xyz.org | N10: 65.3 | O10: Blue | P10: A+ | Q10: =_xlfn.XLOOKUP($R10,SPORT!$B$1:$B$33,SPORT!$A$1:$A$33) -> INDOOR | R10: Shooting | S10: 60061
A11: 10 | B11: =UPPER(_xlfn.CONCAT(C11&" "&D11&" "&F11)) -> MR. TOBY SIMPSON | C11: Mr. | D11: Toby | F11: Simpson | G11: 23732 | H11: Sagittarius | I11: Male | J11: GB | K11: =HLOOKUP($J11,LOCATION!$A$2:$M$3,2,FALSE) -> UK | L11: =_xlfn.XLOOKUP($J11,LOCATION!$A$2:$M$2,LOCATION!$A$1:$M$1) -> English | M11: =LOWER(IF($L11="English",$F11&"."&$D11&"@xyz.org",$F11&"."&$D11&"@xyz.com")) -> simpson.toby@xyz.org | N11: 62.9 | O11: Amber | P11: O+ | Q11: =_xlfn.XLOOKUP($R11,SPORT!$B$1:$B$33,SPORT!$A$1:$A$33) -> OUTDOOR | R11: Cycling Road | S11: 32758
A12: 11 | B12: =UPPER(_xlfn.CONCAT(C12&" "&D12&" "&F12)) -> SIR ETHAN MURPHY | C12: Sir | D12: Ethan | F12: Murphy | G12: 31733 | H12: Scorpio | I12: Male | J12: GB | K12: =HLOOKUP($J12,LOCATION!$A$2:$M$3,2,FALSE) -> UK | L12: =_xlfn.XLOOKUP($J12,LOCATION!$A$2:$M$2,LOCATION!$A$1:$M$1) -> English | M12: =LOWER(IF($L12="English",$F12&"."&$D12&"@xyz.org",$F12&"."&$D12&"@xyz.com")) -> murphy.ethan@xyz.org | N12: 104.3 | O12: Brown | P12: O+ | Q12: =_xlfn.XLOOKUP($R12,SPORT!$B$1:$B$33,SPORT!$A$1:$A$33) -> OUTDOOR | R12: Freestyle Skiing | S12: 99613
A13: 12 | B13: =UPPER(_xlfn.CONCAT(C13&" "&D13&" "&F13)) -> MRS. ASHLEY WOOD | C13: Mrs. | D13: Ashley | F13: Wood | G13: 28412 | H13: Libra | I13: Female | J13: GB | K13: =HLOOKUP($J13,LOCATION!$A$2:$M$3,2,FALSE) -> UK | L13: =_xlfn.XLOOKUP($J13,LOCATION!$A$2:$M$2,LOCATION!$A$1:$M$1) -> English | M13: =LOWER(IF($L13="English",$F13&"."&$D13&"@xyz.org",$F13&"."&$D13&"@xyz.com")) -> wood.ashley@xyz.org | N13: 100.7 | O13: Brown | P13: O+ | Q13: =_xlfn.XLOOKUP($R13,SPORT!$B$1:$B$33,SPORT!$A$1:$A$33) -> OUTDOOR | R13: Archery | S13: 56595
A14: 13 | B14: =UPPER(_xlfn.CONCAT(C14&" "&D14&" "&F14)) -> MS. MEGAN SCOTT | C14: Ms. | D14: Megan | F14: Scott | G14: 28168 | H14: Aquarius | I14: Female | J14: GB | K14: =HLOOKUP($J14,LOCATION!$A$2:$M$3,2,FALSE) -> UK | L14: =_xlfn.XLOOKUP($J14,LOCATION!$A$2:$M$2,LOCATION!$A$1:$M$1) -> English | M14: =LOWER(IF($L14="English",$F14&"."&$D14&"@xyz.org",$F14&"."&$D14&"@xyz.com")) -> scott.megan@xyz.org | N14: 70.9 | O14: Green | P14: A− | Q14: =_xlfn.XLOOKUP($R14,SPORT!$B$1:$B$33,SPORT!$A$1:$A$33) -> OUTDOOR | R14: Rugby | S14: 117408
A15: 14 | B15: =UPPER(_xlfn.CONCAT(C15&" "&D15&" "&F15)) -> HR. HELMUT WEINHAE | C15: Hr. | D15: Helmut | F15: Weinhae | G15: 21788 | H15: Virgo | I15: Male | J15: DE | K15: =HLOOKUP($J15,LOCATION!$A$2:$M$3,2,FALSE) -> GERMANY | L15: =_xlfn.XLOOKUP($J15,LOCATION!$A$2:$M$2,LOCATION!$A$1:$M$1) -> German | M15: =LOWER(IF($L15="English",$F15&"."&$D15&"@xyz.org",$F15&"."&$D15&"@xyz.com")) -> weinhae.helmut@xyz.com | N15: 68.3 | O15: Gray | P15: A+ | Q15: =_xlfn.XLOOKUP($R15,SPORT!$B$1:$B$33,SPORT!$A$1:$A$33) -> OUTDOOR | R15: Canoe Sprint | S15: 64862
A16: 15 | B16: =UPPER(_xlfn.CONCAT(C16&" "&D16&" "&F16)) -> PROF. MILENA SCHOTIN | C16: Prof. | D16: Milena | F16: Schotin | G16: 23804 | H16: Pisces | I16: Female | J16: DE | K16: =HLOOKUP($J16,LOCATION!$A$2:$M$3,2,FALSE) -> GERMANY | L16: =_xlfn.XLOOKUP($J16,LOCATION!$A$2:$M$2,LOCATION!$A$1:$M$1) -> German | M16: =LOWER(IF($L16="English",$F16&"."&$D16&"@xyz.org",$F16&"."&$D16&"@xyz.com")) -> schotin.milena@xyz.com | N16: 105.3 | O16: Gray | P16: O+ | Q16: =_xlfn.XLOOKUP($R16,SPORT!$B$1:$B$33,SPORT!$A$1:$A$33) -> INDOOR | R16: Cycling BMX | S16: 10241
... A39: 38 | B39: =UPPER(_xlfn.CONCAT(C39&" "&D39&" "&F39)) -> M. BERNARD HOARAU-GUYON | C39: M. | D39: Bernard | F39: Hoarau-Guyon | G39: 30327 | H39: Capricorn | I39: Male | J39: FR | K39: =HLOOKUP($J39,LOCATION!$A$2:$M$3,2,FALSE) -> FRANCE | L39: =_xlfn.XLOOKUP($J39,LOCATION!$A$2:$M$2,LOCATION!$A$1:$M$1) -> French | M39: =LOWER(IF($L39="English",$F39&"."&$D39&"@xyz.org",$F39&"."&$D39&"@xyz.com")) -> hoarau-guyon.bernard@xyz.com | N39: 59.7 | O39: Gray | P39: O− | Q39: =_xlfn.XLOOKUP($R39,SPORT!$B$1:$B$33,SPORT!$A$1:$A$33) -> INDOOR | R39: Cycling Track | S39: 71352
A40: 39 | B40: =UPPER(_xlfn.CONCAT(C40&" "&D40&" "&F40)) -> SR. HIDALGO TERCERO | C40: Sr. | D40: Hidalgo | E40: Cantu | F40: Tercero | G40: 31016 | H40: Sagittarius | I40: Male | J40: AG | K40: =HLOOKUP($J40,LOCATION!$A$2:$M$3,2,FALSE) -> ARGENTINA | L40: =_xlfn.XLOOKUP($J40,LOCATION!$A$2:$M$2,LOCATION!$A$1:$M$1) -> Spanish | M40: =LOWER(IF($L40="English",$F40&"."&$D40&"@xyz.org",$F40&"."&$D40&"@xyz.com")) -> tercero.hidalgo@xyz.com | N40: 77.7 | O40: Gray | P40: B− | Q40: =_xlfn.XLOOKUP($R40,SPORT!$B$1:$B$33,SPORT!$A$1:$A$33) -> OUTDOOR | R40: Canoe Slalom | S40: 116376
A41: 40 | B41: =UPPER(_xlfn.CONCAT(C41&" "&D41&" "&F41)) -> SR. HADALGO POLANCO | C41: Sr. | D41: Hadalgo | F41: Polanco | G41: 32314 | H41: Gemini | I41: Male | J41: AG | K41: =HLOOKUP($J41,LOCATION!$A$2:$M$3,2,FALSE) -> ARGENTINA | L41: =_xlfn.XLOOKUP($J41,LOCATION!$A$2:$M$2,LOCATION!$A$1:$M$1) -> Spanish | M41: =LOWER(IF($L41="English",$F41&"."&$D41&"@xyz.org",$F41&"."&$D41&"@xyz.com")) -> polanco.hadalgo@xyz.com | N41: 98 | O41: Blue | P41: A− | Q41: =_xlfn.XLOOKUP($R41,SPORT!$B$1:$B$33,SPORT!$A$1:$A$33) -> OUTDOOR | R41: Beach Volleyball | S41: 114144
A42: 41 | B42: =UPPER(_xlfn.CONCAT(C42&" "&D42&" "&F42)) -> SRA. LAURA OLIVIERA | C42: Sra. | D42: Laura | F42: Oliviera | G42: 27076 | H42: Aquarius | I42: Female | J42: AG | K42: =HLOOKUP($J42,LOCATION!$A$2:$M$3,2,FALSE) -> ARGENTINA | L42: =_xlfn.XLOOKUP($J42,LOCATION!$A$2:$M$2,LOCATION!$A$1:$M$1) -> Spanish | M42: =LOWER(IF($L42="English",$F42&"."&$D42&"@xyz.org",$F42&"."&$D42&"@xyz.com")) -> oliviera.laura@xyz.com | N42: 51.9 | O42: Amber | P42: O− | Q42: =_xlfn.XLOOKUP($R42,SPORT!$B$1:$B$33,SPORT!$A$1:$A$33) -> OUTDOOR | R42: Athletics | S42: 79872
A43: 42 | B43: =UPPER(_xlfn.CONCAT(C43&" "&D43&" "&F43)) -> SRA. AINHOA GARZA | C43: Sra. | D43: Ainhoa | F43: Garza | G43: 32941 | H43: Pisces | I43: Female | J43: ES | K43: =HLOOKUP($J43,LOCATION!$A$2:$M$3,2,FALSE) -> SPAIN | L43: =_xlfn.XLOOKUP($J43,LOCATION!$A$2:$M$2,LOCATION!$A$1:$M$1) -> Spanish | M43: =LOWER(IF($L43="English",$F43&"."&$D43&"@xyz.org",$F43&"."&$D43&"@xyz.com")) -> garza.ainhoa@xyz.com | N43: 55.6 | O43: Brown | P43: O+ | Q43: =_xlfn.XLOOKUP($R43,SPORT!$B$1:$B$33,SPORT!$A$1:$A$33) -> INDOOR | R43: Gymnastics Artistic | S43: 101969
A44: 43 | B44: =UPPER(_xlfn.CONCAT(C44&" "&D44&" "&F44)) -> SRA. ISABEL BANDA | C44: Sra. | D44: Isabel | F44: Banda | G44: 21927 | H44: Capricorn | I44: Female | J44: ES | K44: =HLOOKUP($J44,LOCATION!$A$2:$M$3,2,FALSE) -> SPAIN | L44: =_xlfn.XLOOKUP($J44,LOCATION!$A$2:$M$2,LOCATION!$A$1:$M$1) -> Spanish | M44: =LOWER(IF($L44="English",$F44&"."&$D44&"@xyz.org",$F44&"."&$D44&"@xyz.com")) -> banda.isabel@xyz.com | N44: 102.3 | O44: Amber | P44: O+ | Q44: =_xlfn.XLOOKUP($R44,SPORT!$B$1:$B$33,SPORT!$A$1:$A$33) -> OUTDOOR | R44: Canoe Slalom | S44: 50659
A45: 44 | B45: =UPPER(_xlfn.CONCAT(C45&" "&D45&" "&F45)) -> SRA. CAROLOTA MATEOS | C45: Sra. | D45: Carolota | F45: Mateos | G45: 23952 | H45: Leo | I45: Female | J45: ES | K45: =HLOOKUP($J45,LOCATION!$A$2:$M$3,2,FALSE) -> SPAIN | L45: =_xlfn.XLOOKUP($J45,LOCATION!$A$2:$M$2,LOCATION!$A$1:$M$1) -> Spanish | M45: =LOWER(IF($L45="English",$F45&"."&$D45&"@xyz.org",$F45&"."&$D45&"@xyz.com")) -> mateos.carolota@xyz.com | N45: 58.8 | O45: Gray | P45: O− | Q45: =_xlfn.XLOOKUP($R45,SPORT!$B$1:$B$33,SPORT!$A$1:$A$33) -> OUTDOOR | R45: Athletics | S45: 58215
A46: 45 | B46: =UPPER(_xlfn.CONCAT(C46&" "&D46&" "&F46)) -> MW. ELIZE PRINS | C46: Mw. | D46: Elize | F46: Prins | G46: 22044 | H46: Taurus | I46: Female | J46: DU | K46: =HLOOKUP($J46,LOCATION!$A$2:$M$3,2,FALSE) -> NETHERLANDS | L46: =_xlfn.XLOOKUP($J46,LOCATION!$A$2:$M$2,LOCATION!$A$1:$M$1) -> Dutch | M46: =LOWER(IF($L46="English",$F46&"."&$D46&"@xyz.org",$F46&"."&$D46&"@xyz.com")) -> prins.elize@xyz.com | N46: 63.8 | O46: Blue | P46: O+ | Q46: =_xlfn.XLOOKUP($R46,SPORT!$B$1:$B$33,SPORT!$A$1:$A$33) -> INDOOR | R46: Judo | S46: 39935
A47: 46 | B47: =UPPER(_xlfn.CONCAT(C47&" "&D47&" "&F47)) -> DHR. RYAN PHAM | C47: dhr. | D47: Ryan | F47: Pham | G47: 26940 | H47: Libra | I47: Male | J47: DU | K47: =HLOOKUP($J47,LOCATION!$A$2:$M$3,2,FALSE) -> NETHERLANDS | L47: =_xlfn.XLOOKUP($J47,LOCATION!$A$2:$M$2,LOCATION!$A$1:$M$1) -> Dutch | M47: =LOWER(IF($L47="English",$F47&"."&$D47&"@xyz.org",$F47&"."&$D47&"@xyz.com")) -> pham.ryan@xyz.com | N47: 98.6 | O47: Amber | P47: B+ | Q47: =_xlfn.XLOOKUP($R47,SPORT!$B$1:$B$33,SPORT!$A$1:$A$33) -> OUTDOOR | R47: Beach Volleyball | S47: 44865
A48: 47 | B48: =UPPER(_xlfn.CONCAT(C48&" "&D48&" "&F48)) -> MW ELISE ROTTEVEEL | C48: Mw | D48: Elise | F48: Rotteveel | G48: 24936 | H48: Aries | I48: Female | J48: DU | K48: =HLOOKUP($J48,LOCATION!$A$2:$M$3,2,FALSE) -> NETHERLANDS | L48: =_xlfn.XLOOKUP($J48,LOCATION!$A$2:$M$2,LOCATION!$A$1:$M$1) -> Dutch | M48: =LOWER(IF($L48="English",$F48&"."&$D48&"@xyz.org",$F48&"."&$D48&"@xyz.com")) -> rotteveel.elise@xyz.com | N48: 61.8 | O48: Gray | P48: O− | Q48: =_xlfn.XLOOKUP($R48,SPORT!$B$1:$B$33,SPORT!$A$1:$A$33) -> OUTDOOR | R48: Beach Volleyball | S48: 90478
A49: 48 | B49: =UPPER(_xlfn.CONCAT(C49&" "&D49&" "&F49)) -> FRU. MIRJAM SODERBERG | C49: Fru. | D49: Mirjam | F49: Soderberg | G49: 35567 | H49: Taurus | I49: Female | J49: SV | K49: =HLOOKUP($J49,LOCATION!$A$2:$M$3,2,FALSE) -> SWEDEN | L49: =_xlfn.XLOOKUP($J49,LOCATION!$A$2:$M$2,LOCATION!$A$1:$M$1) -> Swedish | M49: =LOWER(IF($L49="English",$F49&"."&$D49&"@xyz.org",$F49&"."&$D49&"@xyz.com")) -> soderberg.mirjam@xyz.com | N49: 50 | O49: Amber | P49: O+ | Q49: =_xlfn.XLOOKUP($R49,SPORT!$B$1:$B$33,SPORT!$A$1:$A$33) -> OUTDOOR | R49: Football | S49: 38965
A50: 49 | B50: =UPPER(_xlfn.CONCAT(C50&" "&D50&" "&F50)) -> H. BERNDT PALSSON | C50: H. | D50: Berndt | F50: Palsson | G50: 31832 | H50: Pisces | I50: Male | J50: SV | K50: =HLOOKUP($J50,LOCATION!$A$2:$M$3,2,FALSE) -> SWEDEN | L50: =_xlfn.XLOOKUP($J50,LOCATION!$A$2:$M$2,LOCATION!$A$1:$M$1) -> Swedish | M50: =LOWER(IF($L50="English",$F50&"."&$D50&"@xyz.org",$F50&"."&$D50&"@xyz.com")) -> palsson.berndt@xyz.com | N50: 45.9 | O50: Blue | P50: A− | Q50: =_xlfn.XLOOKUP($R50,SPORT!$B$1:$B$33,SPORT!$A$1:$A$33) -> OUTDOOR | R50: Biathlon | S50: 35387
A51: 50 | B51: =UPPER(_xlfn.CONCAT(C51&" "&D51&" "&F51)) -> SR. ADRIANO SOBRINHO | C51: Sr. | D51: Adriano | E51: Pontes | F51: Sobrinho | G51: 34178 | H51: Leo | I51: Male | J51: PR | K51: =HLOOKUP($J51,LOCATION!$A$2:$M$3,2,FALSE) -> BRAZIL | L51: =_xlfn.XLOOKUP($J51,LOCATION!$A$2:$M$2,LOCATION!$A$1:$M$1) -> Portuguese | M51: =LOWER(IF($L51="English",$F51&"."&$D51&"@xyz.org",$F51&"."&$D51&"@xyz.com")) -> sobrinho.adriano@xyz.com | N51: 92.5 | O51: Green | P51: A+ | Q51: =_xlfn.XLOOKUP($R51,SPORT!$B$1:$B$33,SPORT!$A$1:$A$33) -> INDOOR | R51: Swimming | S51: 20532

Sheet SPORT
A1: SPORTS LOCATION | B1: SPORTS
A2: INDOOR | B2: Cycling Track
A3: INDOOR | B3: Boxing
A4: OUTDOOR | B4: Football
A5: OUTDOOR | B5: Alpine Skiing
A6: INDOOR | B6: Water Polo
A7: INDOOR | B7: Fencing
A8: OUTDOOR | B8: Cycling Road
A9: INDOOR | B9: Curling
A10: INDOOR | B10: Shooting
A11: OUTDOOR | B11: Freestyle Skiing
A12: OUTDOOR | B12: Archery
... A33: INDOOR | B33: Swimming

Sheet LOCATION
A1: LANGUAGE | B1: English | C1: Portuguese | D1: English | E1: German | F1: English | G1: German | H1: French | I1: Spanish | J1: Spanish | K1: Dutch | L1: Swedish | M1: Portuguese
A2: COUNTRYCODE | B2: US | C2: BR | D2: GB | E2: DE | F2: OZ | G2: AU | H2: FR | I2: AG | J2: ES | K2: DU | L2: SV | M2: PR
A3: COUNTRY NAME | B3: USA | C3: BRAZIL | D3: UK | E3: GERMANY | F3: AUSTRALIA | G3: AUSTRIA | H3: FRANCE | I3: ARGENTINA | J3: SPAIN | K3: NETHERLANDS | L3: SWEDEN | M3: BRAZIL
